<?xml version='1.0'?>

<robot name="robot" xmlns:xacro="http://www.ros.org/wiki/xacro">

  <xacro:property name="cameraSize" value="0.05"/>
  <xacro:property name="cameraMass" value="0.1"/>

  <xacro:include filename="$(find robot_description)/urdf/robot.gazebo" />
  <xacro:include filename="$(find robot_description)/urdf/materials.xacro" />
  <xacro:include filename="$(find robot_description)/urdf/macros.xacro" />


  <link name='chassis'>
    <pose>0 0 0.1 0 0 0</pose>

    <inertial>
      <mass value="2.5"/>
      <origin xyz="0.0 0 0.05" rpy="0 0 0"/>
      <inertia
          ixx="0.00908" ixy="0" ixz="0"
          iyy="0.0099375" iyz="0"
          izz="0.01752"
      />
    </inertial>

    <collision name='collision'>
      <geometry>
        <box size=".21 .2 .06"/>
      </geometry>
    </collision>

    <visual name='chassis_visual'>
      <origin xyz="0 0 0.05" rpy=" 0 0 0"/>
      <geometry>
        <box size=".21 .2 .06"/>
      </geometry>
    </visual>
  </link>

  <link name="left_wheel_front">
    <!--origin xyz="0.1 0.13 0.1" rpy="0 1.5707 1.5707"/-->
    <collision name="collision">
      <origin xyz="0 0 0" rpy="0 1.5707 1.5707"/>
      <geometry>
        <cylinder radius="0.04" length="0.05"/>
      </geometry>
      <surface>
        <friction>
          <ode>
            <mu>0.1</mu>
            <mu2>0.1</mu2>
          </ode>
      </friction>
      </surface>
    </collision>
    <visual name="left_wheel_front_visual">
      <origin xyz="0 0 0" rpy="0 1.5707 1.5707"/>
      <geometry>
        <cylinder radius="0.04" length="0.04"/>
      </geometry>
    </visual>
    <inertial>
      <mass value="0.8"/>
      <origin xyz="0 0 0" rpy="0 0 0"/>
      <inertia
          ixx="0.000427" ixy="0" ixz="0"
          iyy="0.000427" iyz="0"
          izz="0.00064"
      />
    </inertial>
  </link>


  <link name="left_wheel_middle">
    <!--origin xyz="0.1 0.13 0.1" rpy="0 1.5707 1.5707"/-->
    <collision name="collision">
      <origin xyz="0 0 0.008" rpy="0 1.5707 1.5707"/>
      <geometry>
        <box size=".075 .18 .04"/>
      </geometry>

    </collision>
    <visual name="left_wheel_middle_visual">
      <origin xyz="0 0 0.008" rpy="0 1.5707 1.5707"/>
      <geometry>
        <box size=".075 .18 .04"/>
      </geometry>
    </visual>
    <inertial>
      <origin xyz="0 0 0" rpy="0 1.5707 1.5707"/>
      <mass value="0.4"/>
      <inertia
        ixx="0.00113" ixy="0.0" ixz="0.0"
        iyy="0.000241" iyz="0.0"
        izz="0.0012675"/>
    </inertial>
  </link>


  <link name="left_wheel">
    <!--origin xyz="0.1 0.13 0.1" rpy="0 1.5707 1.5707"/-->
    <collision name="collision">
      <origin xyz="0 0 0" rpy="0 1.5707 1.5707"/>
      <geometry>
        <cylinder radius="0.04" length="0.05"/>
      </geometry>
      <surface>
        <friction>
          <ode>friction
            <mu>1</mu>
            <mu2>1</mu2>
          </ode>
        </friction>
      </surface>
    </collision>
    <visual name="left_whemassel_visual">
      <origin xyz="0 0 0" rpy="0 1.5707 1.5707"/>
      <geometry>
        <cylinder radius="0.04" length="0.04"/>
      </geometry>
    </visual>
    <inertial>
      <origin xyz="0 0 0" rpy="0 1.5707 1.5707"/>
      <mass value="0.8"/>
      <inertia
        ixx="0.000213" ixy="0.0" ixz="0.0"
        iyy="0.000213" iyz="0.0"
        izz="0.00032"/>
    </inertial>
  </link>


  <link name="right_wheel_front">
    <!--origin xyz="0.1 0.13 0.1" rpy="0 1.5707 1.5707"/-->
    <collision name="collision">
      <origin xyz="0 0 0" rpy="0 1.5707 1.5707"/>
      <geometry>
        <cylinder radius="0.04" length="0.05"/>
      </geometry>
      <surface>
        <friction>
          <ode>
            <mu>0.1</mu>
            <mu2>0.1</mu2>
          </ode>
        </friction>
      </surface>
    </collision>
    <visual name="right_wheel_front_visual">
      <origin xyz="0 0 0" rpy="0 1.5707 1.5707"/>
      <geometry>
        <cylinder radius="0.04" length="0.04"/>
      </geometry>
    </visual>
    <inertial>
      <mass value="0.8"/>
      <origin xyz="0 0 0" rpy="0 0 0"/>
      <inertia
          ixx="0.000427" ixy="0" ixz="0"
          iyy="0.000427" iyz="0"
          izz="0.00064"
      />
    </inertial>
  </link>


  <link name="right_wheel_middle">
    <!--origin xyz="0.1 0.13 0.1" rpy="0 1.5707 1.5707"/-->
    <collision name="collision">
      <origin xyz="0 0 0.008" rpy="0 1.5707 1.5707"/>
      <geometry>
        <box size=".075 .18 .04"/>
      </geometry>
    </collision>
    <visual name="right_wheel_middle_visual">
      <origin xyz="0 0 0.008" rpy="0 1.5707 1.5707"/>
      <geometry>
        <box size=".075 .18 .04"/>
      </geometry>
    </visual>
    <inertial>
      <origin xyz="0 0 0" rpy="0 1.5707 1.5707"/>
      <mass value="0.4"/>
      <inertia
        ixx="0.00113" ixy="0.0" ixz="0.0"
        iyy="0.000241" iyz="0.0"
        izz="0.0012675"/>
    </inertial>
  </link>

  <link name="right_wheel">
    <!--origin xyz="0.1 0.13 0.1" rpy="0 1.5707 1.5707"/-->
    <collision name="collision">
      <origin xyz="0 0 0" rpy="0 1.5707 1.5707"/>
      <geometry>
        <cylinder radius="0.04" length="0.05"/>
      </geometry>
      <surface>
        <friction>
          <ode>
            <mu>1</mu>
            <mu2>1</mu2>
          </ode>
        </friction>
      </surface>
    </collision>
    <visual name="right_wheel_visual">
      <origin xyz="0 0 0" rpy="0 1.5707 1.5707"/>
      <geometry>
        <cylinder radius="0.04" length="0.04"/>
      </geometry>
    </visual>
    <inertial>
      <origin xyz="0 0 0" rpy="0 1.5707 1.5707"/>
      <mass value="0.8"/>
      <inertia
        ixx="0.000213" ixy="0.0" ixz="0.0"
        iyy="0.000213" iyz="0.0"
        izz="0.00032"/>
    </inertial>
  </link>


  <joint type="continuous" name="left_wheel_hinge">
    <origin xyz="0.1 0.15 0" rpy="0 0 0"/>
    <child link="left_wheel"/>
    <parent link="chassis"/>
    <axis xyz="0 1 0" rpy="0 0 0"/>
    <limit effort="100" velocity="100"/>
    <joint_properties damping="0.0" friction="0.0"/>
  </joint>

  <joint type="continuous" name="right_wheel_hinge">
    <origin xyz="0.1 -0.15 0" rpy="0 0 0"/>
    <child link="right_wheel"/>
    <parent link="chassis"/>
    <axis xyz="0 1 0" rpy="0 0 0"/>
    <limit effort="100" velocity="100"/>
    <joint_properties damping="0.0" friction="0.0"/>
  </joint>

  <joint type="continuous" name="left_wheel_front_hinge">
    <origin xyz="-0.1 0.15 0" rpy="0 0 0"/>
    <child link="left_wheel_front"/>
    <parent link="chassis"/>
    <axis xyz="0 1 0" rpy="0 0 0"/>
    <limit effort="100" velocity="100"/>
    <joint_properties damping="0.0" friction="0.0"/>
  </joint>

  <joint type="fixed" name="left_wheel_middle_hinge">
    <origin xyz="0 0.15 0.00" rpy="0 0 0"/>
    <child link="left_wheel_middle"/>
    <parent link="chassis"/>
    <axis xyz="0 1 0" rpy="0 0 0"/>
    <limit effort="100" velocity="100"/>
    <joint_properties damping="0.0" friction="0.0"/>
  </joint>

  <joint type="continuous" name="right_wheel_front_hinge">
    <origin xyz="-0.1 -0.15 0" rpy="0 0 0"/>
    <child link="right_wheel_front"/>
    <parent link="chassis"/>
    <axis xyz="0 1 0" rpy="0 0 0"/>
    <limit effort="100" velocity="100"/>
    <joint_properties damping="0.0" friction="0.0"/>
  </joint>

  <joint type="fixed" name="right_wheel_middle_hinge">
    <origin xyz="0 -0.15 0.00" rpy="0 0 0"/>
    <child link="right_wheel_middle"/>
    <parent link="chassis"/>
    <axis xyz="0 1 0" rpy="0 0 0"/>
    <limit effort="100" velocity="100"/>
    <joint_properties damping="0.0" friction="0.0"/>
  </joint>

  <link name="camera">
    <collision>
      <origin xyz="0 0 0" rpy="0 0 -3.1415"/>
      <geometry>
        <box size="${cameraSize} ${cameraSize} ${cameraSize}"/>
      </geometry>
    </collision>

    <visual>
      <origin xyz="0 0 0" rpy="0 0 -3.1415"/>
      <geometry>
        <box size="${cameraSize} ${cameraSize} ${cameraSize}"/>
      </geometry>
      <material name="green"/>
    </visual>

    <inertial>
      <mass value="${cameraMass}" />
      <origin xyz="0 0 0" rpy="0 0 -3.1415"/>
      <box_inertia m="${cameraMass}" x="${cameraSize}" y="${cameraSize}" z="${cameraSize}" />
      <inertia ixx="1e-6" ixy="0" ixz="0" iyy="1e-6" iyz="0" izz="1e-6" />
    </inertial>
  </link>

  <joint name="camera_joint" type="fixed">
    <axis xyz="0.18 1 0" />
    <origin xyz="-0.11 0 0.1" rpy="0 0 -3.1415"/>
    <parent link="chassis"/>
    <child link="camera"/>
  </joint>





</robot>
